<?xml version="1.0" encoding="utf-8"?><messages><msg code="0" type="2">Start Time: Sunday, May 4, 2025 10:51:28 AM</msg><msg code="0" type="0">Raster clipped to study area.</msg><msg code="1" type="100">Traceback (most recent call last):
﻿  File "C:\Users\cdwira1\Downloads\MY GEOG PROGRAMMING WORK\Shoreline_Extractor\Shoreline_Extractor.pyt", line 138, in execute
    green_index = next(i for i, b in enumerate(band_names) if green_band_name.lower() in b.lower()) + 1
                  ^^^^^^^^^^^^^^^^^^^^^^^^^^^^^^^^^^^^^^^^^^^^^^^^^^^^^^^^^^^^^^^^^^^^^^^^^^^^^^^^^
﻿StopIteration
﻿
During handling of the above exception, another exception occurred:

﻿Traceback (most recent call last):
﻿  File "C:\Users\cdwira1\Downloads\MY GEOG PROGRAMMING WORK\Shoreline_Extractor\Shoreline_Extractor.pyt", line 141, in execute
    raise RuntimeError("One or both specified band names were not found in the raster.")
﻿RuntimeError: One or both specified band names were not found in the raster.
﻿
If you suspect this is an IPython 8.18.1 bug, please report it at:
    https://github.com/ipython/ipython/issues
or send an email to the mailing list at ipython-dev@python.org

You can print a more detailed traceback right now with "%tb", or use "%debug"
to interactively debug it.

Extra-detailed tracebacks for bug-reporting purposes can be enabled via:
    %config Application.verbose_crash=True

</msg><msg code="-2147467259" type="100">Failed to execute (Tool).</msg><msg code="0" type="3">Failed at Sunday, May 4, 2025 10:51:54 AM (Elapsed Time: 25.35 seconds)</msg></messages>